Workbook
Name _Toc89451387: 'CAF Effort'!$B$2
Name _Toc89451388: 'CAF Effort'!$B$213

Sheet Effort Estimation
A1: Theme | B1: EPIC | C1: User Stories | D1: Task | E1: Point Value | F1: ~ Effort in Man Days | G1: Roles
A2: DI Upgrade | E2: 0 | F2: 0 | G2: .Net Developer
B3: Login | C3: Authentication | E3: 8 | F3: =IF(Table1[[#This Row],[Point Value]]=1,1,IF(Table1[[#This Row],[Point Value]]=2,2,IF(Table1[[#This Row],[Point Value]]=3,3,IF(Table1[[#This Row],[Point Value]]=5,4, IF(Table1[[#This Row],[Point Value]]=8,5, IF(Table1[[#This Row],[Point Value]]=13,10, IF(Table1[[#This Row],[Point Value]]=20, 15,IF(Table1[[#This Row],[Point Value]]=40,40)))))))) -> 5 | G3: .Net Developer
C4: SSO Inegration | E4: 8 | F4: =IF(Table1[[#This Row],[Point Value]]=1,1,IF(Table1[[#This Row],[Point Value]]=2,2,IF(Table1[[#This Row],[Point Value]]=3,3,IF(Table1[[#This Row],[Point Value]]=5,4, IF(Table1[[#This Row],[Point Value]]=8,5, IF(Table1[[#This Row],[Point Value]]=13,10, IF(Table1[[#This Row],[Point Value]]=20, 15,IF(Table1[[#This Row],[Point Value]]=40,40)))))))) -> 5 | G4: .Net Developer
C5: Authorization
C6: Passwod Management | E6: 5 | F6: =IF(Table1[[#This Row],[Point Value]]=1,1,IF(Table1[[#This Row],[Point Value]]=2,2,IF(Table1[[#This Row],[Point Value]]=3,3,IF(Table1[[#This Row],[Point Value]]=5,4, IF(Table1[[#This Row],[Point Value]]=8,5, IF(Table1[[#This Row],[Point Value]]=13,10, IF(Table1[[#This Row],[Point Value]]=20, 15,IF(Table1[[#This Row],[Point Value]]=40,40)))))))) -> 4 | G6: .Net Developer
B7: Dashboard | C7: Dashboard | E7: 8 | F7: =IF(Table1[[#This Row],[Point Value]]=1,1,IF(Table1[[#This Row],[Point Value]]=2,2,IF(Table1[[#This Row],[Point Value]]=3,3,IF(Table1[[#This Row],[Point Value]]=5,4, IF(Table1[[#This Row],[Point Value]]=8,5, IF(Table1[[#This Row],[Point Value]]=13,10, IF(Table1[[#This Row],[Point Value]]=20, 15,IF(Table1[[#This Row],[Point Value]]=40,40)))))))) -> 5 | G7: .Net Developer
C8: Reports | E8: 8 | F8: =IF(Table1[[#This Row],[Point Value]]=1,1,IF(Table1[[#This Row],[Point Value]]=2,2,IF(Table1[[#This Row],[Point Value]]=3,3,IF(Table1[[#This Row],[Point Value]]=5,4, IF(Table1[[#This Row],[Point Value]]=8,5, IF(Table1[[#This Row],[Point Value]]=13,10, IF(Table1[[#This Row],[Point Value]]=20, 15,IF(Table1[[#This Row],[Point Value]]=40,40)))))))) -> 5 | G8: .Net Developer
C9: Search | E9: 8 | F9: =IF(Table1[[#This Row],[Point Value]]=1,1,IF(Table1[[#This Row],[Point Value]]=2,2,IF(Table1[[#This Row],[Point Value]]=3,3,IF(Table1[[#This Row],[Point Value]]=5,4, IF(Table1[[#This Row],[Point Value]]=8,5, IF(Table1[[#This Row],[Point Value]]=13,10, IF(Table1[[#This Row],[Point Value]]=20, 15,IF(Table1[[#This Row],[Point Value]]=40,40)))))))) -> 5 | G9: .Net Developer
C10: Report Export | E10: 5 | F10: =IF(Table1[[#This Row],[Point Value]]=1,1,IF(Table1[[#This Row],[Point Value]]=2,2,IF(Table1[[#This Row],[Point Value]]=3,3,IF(Table1[[#This Row],[Point Value]]=5,4, IF(Table1[[#This Row],[Point Value]]=8,5, IF(Table1[[#This Row],[Point Value]]=13,10, IF(Table1[[#This Row],[Point Value]]=20, 15,IF(Table1[[#This Row],[Point Value]]=40,40)))))))) -> 4 | G10: .Net Developer
C11: Audit Logs | E11: 13 | F11: =IF(Table1[[#This Row],[Point Value]]=1,1,IF(Table1[[#This Row],[Point Value]]=2,2,IF(Table1[[#This Row],[Point Value]]=3,3,IF(Table1[[#This Row],[Point Value]]=5,4, IF(Table1[[#This Row],[Point Value]]=8,5, IF(Table1[[#This Row],[Point Value]]=13,10, IF(Table1[[#This Row],[Point Value]]=20, 15,IF(Table1[[#This Row],[Point Value]]=40,40)))))))) -> 10 | G11: .Net Developer
B12: Maintenance | C12: Approver List | E12: 8 | F12: =IF(Table1[[#This Row],[Point Value]]=1,1,IF(Table1[[#This Row],[Point Value]]=2,2,IF(Table1[[#This Row],[Point Value]]=3,3,IF(Table1[[#This Row],[Point Value]]=5,4, IF(Table1[[#This Row],[Point Value]]=8,5, IF(Table1[[#This Row],[Point Value]]=13,10, IF(Table1[[#This Row],[Point Value]]=20, 15,IF(Table1[[#This Row],[Point Value]]=40,40)))))))) -> 5 | G12: .Net Developer
C13: Customer | E13: 8 | F13: =IF(Table1[[#This Row],[Point Value]]=1,1,IF(Table1[[#This Row],[Point Value]]=2,2,IF(Table1[[#This Row],[Point Value]]=3,3,IF(Table1[[#This Row],[Point Value]]=5,4, IF(Table1[[#This Row],[Point Value]]=8,5, IF(Table1[[#This Row],[Point Value]]=13,10, IF(Table1[[#This Row],[Point Value]]=20, 15,IF(Table1[[#This Row],[Point Value]]=40,40)))))))) -> 5 | G13: .Net Developer
C14: Customer Group | E14: 8 | F14: =IF(Table1[[#This Row],[Point Value]]=1,1,IF(Table1[[#This Row],[Point Value]]=2,2,IF(Table1[[#This Row],[Point Value]]=3,3,IF(Table1[[#This Row],[Point Value]]=5,4, IF(Table1[[#This Row],[Point Value]]=8,5, IF(Table1[[#This Row],[Point Value]]=13,10, IF(Table1[[#This Row],[Point Value]]=20, 15,IF(Table1[[#This Row],[Point Value]]=40,40)))))))) -> 5 | G14: .Net Developer
C15: Configuration | E15: 8 | F15: =IF(Table1[[#This Row],[Point Value]]=1,1,IF(Table1[[#This Row],[Point Value]]=2,2,IF(Table1[[#This Row],[Point Value]]=3,3,IF(Table1[[#This Row],[Point Value]]=5,4, IF(Table1[[#This Row],[Point Value]]=8,5, IF(Table1[[#This Row],[Point Value]]=13,10, IF(Table1[[#This Row],[Point Value]]=20, 15,IF(Table1[[#This Row],[Point Value]]=40,40)))))))) -> 5 | G15: .Net Developer
C16: Commercial Unit | E16: 8 | F16: =IF(Table1[[#This Row],[Point Value]]=1,1,IF(Table1[[#This Row],[Point Value]]=2,2,IF(Table1[[#This Row],[Point Value]]=3,3,IF(Table1[[#This Row],[Point Value]]=5,4, IF(Table1[[#This Row],[Point Value]]=8,5, IF(Table1[[#This Row],[Point Value]]=13,10, IF(Table1[[#This Row],[Point Value]]=20, 15,IF(Table1[[#This Row],[Point Value]]=40,40)))))))) -> 5 | G16: .Net Developer
C17: Invoice Footer | E17: 5 | F17: =IF(Table1[[#This Row],[Point Value]]=1,1,IF(Table1[[#This Row],[Point Value]]=2,2,IF(Table1[[#This Row],[Point Value]]=3,3,IF(Table1[[#This Row],[Point Value]]=5,4, IF(Table1[[#This Row],[Point Value]]=8,5, IF(Table1[[#This Row],[Point Value]]=13,10, IF(Table1[[#This Row],[Point Value]]=20, 15,IF(Table1[[#This Row],[Point Value]]=40,40)))))))) -> 4 | G17: .Net Developer
C18: Location | E18: 5 | F18: =IF(Table1[[#This Row],[Point Value]]=1,1,IF(Table1[[#This Row],[Point Value]]=2,2,IF(Table1[[#This Row],[Point Value]]=3,3,IF(Table1[[#This Row],[Point Value]]=5,4, IF(Table1[[#This Row],[Point Value]]=8,5, IF(Table1[[#This Row],[Point Value]]=13,10, IF(Table1[[#This Row],[Point Value]]=20, 15,IF(Table1[[#This Row],[Point Value]]=40,40)))))))) -> 4 | G18: .Net Developer
C19: Sales Group | E19: 5 | F19: =IF(Table1[[#This Row],[Point Value]]=1,1,IF(Table1[[#This Row],[Point Value]]=2,2,IF(Table1[[#This Row],[Point Value]]=3,3,IF(Table1[[#This Row],[Point Value]]=5,4, IF(Table1[[#This Row],[Point Value]]=8,5, IF(Table1[[#This Row],[Point Value]]=13,10, IF(Table1[[#This Row],[Point Value]]=20, 15,IF(Table1[[#This Row],[Point Value]]=40,40)))))))) -> 4 | G19: .Net Developer
C20: Sales Office | E20: 5 | F20: =IF(Table1[[#This Row],[Point Value]]=1,1,IF(Table1[[#This Row],[Point Value]]=2,2,IF(Table1[[#This Row],[Point Value]]=3,3,IF(Table1[[#This Row],[Point Value]]=5,4, IF(Table1[[#This Row],[Point Value]]=8,5, IF(Table1[[#This Row],[Point Value]]=13,10, IF(Table1[[#This Row],[Point Value]]=20, 15,IF(Table1[[#This Row],[Point Value]]=40,40)))))))) -> 4 | G20: .Net Developer
C21: Sales Org | E21: 5 | F21: =IF(Table1[[#This Row],[Point Value]]=1,1,IF(Table1[[#This Row],[Point Value]]=2,2,IF(Table1[[#This Row],[Point Value]]=3,3,IF(Table1[[#This Row],[Point Value]]=5,4, IF(Table1[[#This Row],[Point Value]]=8,5, IF(Table1[[#This Row],[Point Value]]=13,10, IF(Table1[[#This Row],[Point Value]]=20, 15,IF(Table1[[#This Row],[Point Value]]=40,40)))))))) -> 4 | G21: .Net Developer
C22: Site Admin | E22: 5 | F22: =IF(Table1[[#This Row],[Point Value]]=1,1,IF(Table1[[#This Row],[Point Value]]=2,2,IF(Table1[[#This Row],[Point Value]]=3,3,IF(Table1[[#This Row],[Point Value]]=5,4, IF(Table1[[#This Row],[Point Value]]=8,5, IF(Table1[[#This Row],[Point Value]]=13,10, IF(Table1[[#This Row],[Point Value]]=20, 15,IF(Table1[[#This Row],[Point Value]]=40,40)))))))) -> 4 | G22: .Net Developer
B23: Cloud Development | C23: Setting up MS Defender | E23: 8 | F23: =IF(Table1[[#This Row],[Point Value]]=1,1,IF(Table1[[#This Row],[Point Value]]=2,2,IF(Table1[[#This Row],[Point Value]]=3,3,IF(Table1[[#This Row],[Point Value]]=5,4, IF(Table1[[#This Row],[Point Value]]=8,5, IF(Table1[[#This Row],[Point Value]]=13,10, IF(Table1[[#This Row],[Point Value]]=20, 15,IF(Table1[[#This Row],[Point Value]]=40,40)))))))) -> 5 | G23: Azure Developer
C24: Setting up Azure Storage | E24: 8 | F24: =IF(Table1[[#This Row],[Point Value]]=1,1,IF(Table1[[#This Row],[Point Value]]=2,2,IF(Table1[[#This Row],[Point Value]]=3,3,IF(Table1[[#This Row],[Point Value]]=5,4, IF(Table1[[#This Row],[Point Value]]=8,5, IF(Table1[[#This Row],[Point Value]]=13,10, IF(Table1[[#This Row],[Point Value]]=20, 15,IF(Table1[[#This Row],[Point Value]]=40,40)))))))) -> 5 | G24: Azure Developer
B25: UX | C25: UI Design | E25: 40 | F25: =IF(Table1[[#This Row],[Point Value]]=1,1,IF(Table1[[#This Row],[Point Value]]=2,2,IF(Table1[[#This Row],[Point Value]]=3,3,IF(Table1[[#This Row],[Point Value]]=5,4, IF(Table1[[#This Row],[Point Value]]=8,5, IF(Table1[[#This Row],[Point Value]]=13,10, IF(Table1[[#This Row],[Point Value]]=20, 15,IF(Table1[[#This Row],[Point Value]]=40,40)))))))) -> 40 | G25: UX Developer
C26: JS Development | E26: 13 | F26: =IF(Table1[[#This Row],[Point Value]]=1,1,IF(Table1[[#This Row],[Point Value]]=2,2,IF(Table1[[#This Row],[Point Value]]=3,3,IF(Table1[[#This Row],[Point Value]]=5,4, IF(Table1[[#This Row],[Point Value]]=8,5, IF(Table1[[#This Row],[Point Value]]=13,10, IF(Table1[[#This Row],[Point Value]]=20, 15,IF(Table1[[#This Row],[Point Value]]=40,40)))))))) -> 10 | G26: UX Developer
B27: Testing | C27: Unit Testing | E27: 13 | F27: =IF(Table1[[#This Row],[Point Value]]=1,1,IF(Table1[[#This Row],[Point Value]]=2,2,IF(Table1[[#This Row],[Point Value]]=3,3,IF(Table1[[#This Row],[Point Value]]=5,4, IF(Table1[[#This Row],[Point Value]]=8,5, IF(Table1[[#This Row],[Point Value]]=13,10, IF(Table1[[#This Row],[Point Value]]=20, 15,IF(Table1[[#This Row],[Point Value]]=40,40)))))))) -> 10 | G27: .Net Developer
C28: SIT | E28: 40 | F28: =IF(Table1[[#This Row],[Point Value]]=1,1,IF(Table1[[#This Row],[Point Value]]=2,2,IF(Table1[[#This Row],[Point Value]]=3,3,IF(Table1[[#This Row],[Point Value]]=5,4, IF(Table1[[#This Row],[Point Value]]=8,5, IF(Table1[[#This Row],[Point Value]]=13,10, IF(Table1[[#This Row],[Point Value]]=20, 15,IF(Table1[[#This Row],[Point Value]]=40,40)))))))) -> 40 | G28: Tester
C29: UAT | E29: 13 | F29: =IF(Table1[[#This Row],[Point Value]]=1,1,IF(Table1[[#This Row],[Point Value]]=2,2,IF(Table1[[#This Row],[Point Value]]=3,3,IF(Table1[[#This Row],[Point Value]]=5,4, IF(Table1[[#This Row],[Point Value]]=8,5, IF(Table1[[#This Row],[Point Value]]=13,10, IF(Table1[[#This Row],[Point Value]]=20, 15,IF(Table1[[#This Row],[Point Value]]=40,40)))))))) -> 10 | G29: Tester
C30: PIV | E30: 2 | F30: =IF(Table1[[#This Row],[Point Value]]=1,1,IF(Table1[[#This Row],[Point Value]]=2,2,IF(Table1[[#This Row],[Point Value]]=3,3,IF(Table1[[#This Row],[Point Value]]=5,4, IF(Table1[[#This Row],[Point Value]]=8,5, IF(Table1[[#This Row],[Point Value]]=13,10, IF(Table1[[#This Row],[Point Value]]=20, 15,IF(Table1[[#This Row],[Point Value]]=40,40)))))))) -> 2 | G30: Tester
B31: DB Development | C31: DB Admin | E31: 13 | F31: =IF(Table1[[#This Row],[Point Value]]=1,1,IF(Table1[[#This Row],[Point Value]]=2,2,IF(Table1[[#This Row],[Point Value]]=3,3,IF(Table1[[#This Row],[Point Value]]=5,4, IF(Table1[[#This Row],[Point Value]]=8,5, IF(Table1[[#This Row],[Point Value]]=13,10, IF(Table1[[#This Row],[Point Value]]=20, 15,IF(Table1[[#This Row],[Point Value]]=40,40)))))))) -> 10 | G31: Backend DBA
C32: DB Development | E32: 13 | F32: =IF(Table1[[#This Row],[Point Value]]=1,1,IF(Table1[[#This Row],[Point Value]]=2,2,IF(Table1[[#This Row],[Point Value]]=3,3,IF(Table1[[#This Row],[Point Value]]=5,4, IF(Table1[[#This Row],[Point Value]]=8,5, IF(Table1[[#This Row],[Point Value]]=13,10, IF(Table1[[#This Row],[Point Value]]=20, 15,IF(Table1[[#This Row],[Point Value]]=40,40)))))))) -> 10 | G32: Backend Developer
C33: Azure Development | E33: 13 | F33: =IF(Table1[[#This Row],[Point Value]]=1,1,IF(Table1[[#This Row],[Point Value]]=2,2,IF(Table1[[#This Row],[Point Value]]=3,3,IF(Table1[[#This Row],[Point Value]]=5,4, IF(Table1[[#This Row],[Point Value]]=8,5, IF(Table1[[#This Row],[Point Value]]=13,10, IF(Table1[[#This Row],[Point Value]]=20, 15,IF(Table1[[#This Row],[Point Value]]=40,40)))))))) -> 10 | G33: Azure DevOps Developer
B34: DevSecOps Pipeline | C34: Create Project | E34: 1 | F34: =IF(Table1[[#This Row],[Point Value]]=1,1,IF(Table1[[#This Row],[Point Value]]=2,2,IF(Table1[[#This Row],[Point Value]]=3,3,IF(Table1[[#This Row],[Point Value]]=5,4, IF(Table1[[#This Row],[Point Value]]=8,5, IF(Table1[[#This Row],[Point Value]]=13,10, IF(Table1[[#This Row],[Point Value]]=20, 15,IF(Table1[[#This Row],[Point Value]]=40,40)))))))) -> 1 | G34: Azure DevOps Developer
C35: Create Azure Dashbaords | E35: 8 | F35: =IF(Table1[[#This Row],[Point Value]]=1,1,IF(Table1[[#This Row],[Point Value]]=2,2,IF(Table1[[#This Row],[Point Value]]=3,3,IF(Table1[[#This Row],[Point Value]]=5,4, IF(Table1[[#This Row],[Point Value]]=8,5, IF(Table1[[#This Row],[Point Value]]=13,10, IF(Table1[[#This Row],[Point Value]]=20, 15,IF(Table1[[#This Row],[Point Value]]=40,40)))))))) -> 5 | G35: Azure DevOps Developer
C36: Create Repo | E36: 1 | F36: =IF(Table1[[#This Row],[Point Value]]=1,1,IF(Table1[[#This Row],[Point Value]]=2,2,IF(Table1[[#This Row],[Point Value]]=3,3,IF(Table1[[#This Row],[Point Value]]=5,4, IF(Table1[[#This Row],[Point Value]]=8,5, IF(Table1[[#This Row],[Point Value]]=13,10, IF(Table1[[#This Row],[Point Value]]=20, 15,IF(Table1[[#This Row],[Point Value]]=40,40)))))))) -> 1 | G36: Azure DevOps Developer
C37: Create Artifacts | E37: 3 | F37: =IF(Table1[[#This Row],[Point Value]]=1,1,IF(Table1[[#This Row],[Point Value]]=2,2,IF(Table1[[#This Row],[Point Value]]=3,3,IF(Table1[[#This Row],[Point Value]]=5,4, IF(Table1[[#This Row],[Point Value]]=8,5, IF(Table1[[#This Row],[Point Value]]=13,10, IF(Table1[[#This Row],[Point Value]]=20, 15,IF(Table1[[#This Row],[Point Value]]=40,40)))))))) -> 3 | G37: Azure DevOps Developer
C38: Setup Pipeline | E38: 8 | F38: =IF(Table1[[#This Row],[Point Value]]=1,1,IF(Table1[[#This Row],[Point Value]]=2,2,IF(Table1[[#This Row],[Point Value]]=3,3,IF(Table1[[#This Row],[Point Value]]=5,4, IF(Table1[[#This Row],[Point Value]]=8,5, IF(Table1[[#This Row],[Point Value]]=13,10, IF(Table1[[#This Row],[Point Value]]=20, 15,IF(Table1[[#This Row],[Point Value]]=40,40)))))))) -> 5 | G38: Azure DevOps Developer
C39: Security Test Plans | E39: 8 | F39: =IF(Table1[[#This Row],[Point Value]]=1,1,IF(Table1[[#This Row],[Point Value]]=2,2,IF(Table1[[#This Row],[Point Value]]=3,3,IF(Table1[[#This Row],[Point Value]]=5,4, IF(Table1[[#This Row],[Point Value]]=8,5, IF(Table1[[#This Row],[Point Value]]=13,10, IF(Table1[[#This Row],[Point Value]]=20, 15,IF(Table1[[#This Row],[Point Value]]=40,40)))))))) -> 5 | G39: Azure DevOps Developer
B40: Project Management | C40: Scrum Master/PM | F40: 50 | G40: Project Manager
...

Sheet Resources and Effort
B1: Resources Required | T1: Effort
A2: App Name | B2: SDA | C2: SA | D2: PM | E2: BA | F2: Architect | G2: Tech Lead | H2: Dev1 | I2: Dev2 | J2: Mobile Lead | K2: Mobile Dev | L2: Test Lead | M2: Test Engineer | N2: DBA | O2: DB Developer | P2: UX | Q2: UI | R2: Cloud Architect | S2: DevOps Engineer | T2: Man Hours | U2: Man Days | V2: Man Months
A3: DI | B3: ü | C3: ü | D3: ü | E3: ü | F3: ü | G3: ü | H3: ü | I3: ü | J3: ý | K3: ý | L3: ü | M3: ü | N3: ü | O3: ü | P3: ü | Q3: ü | R3: ü | S3: ü | T3: 5520 | U3: 690 | V3: =U3/20 -> 34.5
A4: Survey | B4: ü | C4: ü | D4: ü | E4: ü | F4: ü | G4: ü | H4: ü | I4: ü | J4: ü | K4: ü | L4: ü | M4: ü | N4: ü | O4: ü | P4: ü | Q4: ü | R4: ü | S4: ü | T4: 5936 | U4: 742 | V4: 37.1
A5: CWT | B5: ü | C5: ü | D5: ü | E5: ü | F5: ü | G5: ü | H5: ü | I5: ü | J5: ý | K5: ý | L5: ü | M5: ü | N5: ü | O5: ü | P5: ü | Q5: ü | R5: ü | S5: ü | T5: 4976 | U5: 622 | V5: 31
A6: CAF | B6: ü | C6: ü | D6: ü | E6: ü | F6: ü | G6: ü | H6: ü | I6: ü | J6: ý | K6: ý | L6: ü | M6: ü | N6: ü | O6: ü | P6: ü | Q6: ü | R6: ü | S6: ü | T6: 12400 | U6: 1550 | V6: 78
A7: R&I | B7: ý | C7: ý | D7: ü | E7: ü | F7: ý | G7: ü | H7: ü | I7: ý | J7: ý | K7: ý | L7: ý | M7: ü | N7: ý | O7: ý | P7: ý | Q7: ý | R7: ý | S7: ý | T7: 680 | U7: =T7/8 -> 85 | V7: =T7/200 -> 3.4
A8: BBS | B8: ý | C8: ý | D8: ü | E8: ü | F8: ý | G8: ü | H8: ü | I8: ü | J8: ý | K8: ý | L8: ý | M8: ü | N8: ý | O8: ý | P8: ý | Q8: ý | R8: ý | S8: ý | T8: 992.0625 | U8: 90.125 | V8: =T8/200 -> 4.9603125
A9: Cadence | B9: ý | C9: ý | D9: ü | E9: ü | F9: ý | G9: ü | H9: ü | I9: ý | J9: ý | K9: ý | L9: ý | M9: ü | N9: ý | O9: ý | P9: ý | Q9: ý | R9: ý | S9: ý | T9: 1208 | U9: =T9/8 -> 151 | V9: =T9/200 -> 6.04
A12: App Name | B12: Man Hours | C12: Man Days | D12: Man Months
A13: DI | B13: 5520 | C13: 690 | D13: =C13/20 -> 34.5
A14: Survey | B14: 5936 | C14: 742 | D14: 37.1
A15: CWT | B15: 4976 | C15: 622 | D15: 31
A16: CAF | B16: 12400 | C16: 1550 | D16: 78
A17: R&I | B17: 921 | C17: 115.125 | D17: 5.75625
A18: BBS | B18: 1647 | C18: 205.875 | D18: 10.29375
A19: Cadence | B19: 2728 | C19: 341 | D19: 17.05
A20: Totals | B20: =SUM(B13:B19) -> 34128 | C20: =SUM(C13:C19) -> 4266 | D20: =SUM(D13:D19) -> 213.7

Sheet Complexity Summary
A1: App Name | B1: User Stories | C1: Tasks | D1: Sub Tasks | E1: Web Forms
A2: Digitalised Invoice (DI) | B2: 36 | C2: 60 | D2: 8 | E2: ='All apps Estimation Summary'!B23 -> 82
A3: Survey App (+Mobile) | B3: 16 | C3: 82 | D3: 44 | E3: 35
A4: Credit Application Form (CAF) | B4: 24 | C4: 95 | D4: 125 | E4: 120
A5: Certificate of Withholding Tax (CWT) | B5: 13 | C5: 49 | D5: 5 | E5: =Table9[[#Totals],[Web Forms]] -> 22
A6: BBS | B6: =BBS!C159 -> 24 | C6: =BBS!D159 -> 90 | D6: =BBS!E159 -> 68 | E6: =BBS!A159 -> 37
A7: Cadence | B7: =Cadence!C34 -> 15 | C7: =Cadence!D34 -> 27 | D7: =Cadence!E34 -> 18 | E7: =Cadence!A34 -> 23
A8: Risk & Insurance | B8: ='Risk & Insurance'!C59 -> 5 | C8: ='Risk & Insurance'!D59 -> 22 | D8: ='Risk & Insurance'!E59 -> 10 | E8: ='Risk & Insurance'!A59 -> 13

Sheet All apps Estimation Summary
A1: CCBPI Modernization Estimation | B1: Digitalised Invoice (DI) | E1: Survey App (+Mobile) | H1: Credit Application Form (CAF) | K1: Certificate of Withholding Tax (CWT) | N1: Risk & Insurance Portal | Q1: Cadence | T1: BBS
A2: Roles | B2: Effort In Hours | C2: Effotrt In Days | D2: Effort In Months | E2: Effort In Hours | F2: Effotrt In Days | G2: Effort In Months | H2: Effort In Hours | I2: Effotrt In Days | J2: Effort In Months | K2: Effort In Hours | L2: Effotrt In Days | M2: Effort In Months | N2: Effort In Hours | O2: Effotrt In Days | P2: Effort In Months | Q2: Effort In Hours | R2: Effotrt In Days | S2: Effort In Months | T2: Effort In Hours | U2: Effotrt In Days | V2: Effort In Months
A3: SDA | B3: =C3*8 -> 56 | C3: 7 | D3: =C3/20 -> 0.35 | E3: =F3*8 -> 56 | F3: 7 | G3: =F3/20 -> 0.35 | H3: =I3*8 -> 120 | I3: 15 | J3: =I3/20 -> 0.75 | K3: =L3*8 -> 56 | L3: 7 | M3: =L3/20 -> 0.35
A4: SA | B4: =C4*8 -> 56 | C4: 7 | D4: =C4/20 -> 0.35 | E4: =F4*8 -> 56 | F4: 7 | G4: =F4/20 -> 0.35 | H4: =I4*8 -> 120 | I4: 15 | J4: =I4/20 -> 0.75 | K4: =L4*8 -> 56 | L4: 7 | M4: =L4/20 -> 0.35
A5: PM | B5: =C5*8 -> 272 | C5: 34 | D5: =ROUND(C5/20, 0) -> 2 | E5: =F5*8 -> 336 | F5: 42 | G5: =ROUND(F5/20,0) -> 2 | H5: =I5*8 -> 712 | I5: 89 | J5: =ROUND(I5/20,0) -> 4 | K5: =L5*8 -> 256 | L5: 32 | M5: =ROUND(L5/20, 0) -> 2 | N5: 111 | O5: =N5/8 -> 13.875 | P5: =O5/20 -> 0.69375 | Q5: 183 | R5: =Q5/8 -> 22.875 | S5: =R5/20 -> 1.14375 | T5: 253 | U5: =T5/8 -> 31.625 | V5: =U5/20 -> 1.58125
A6: BA | B6: =C6*8 -> 272 | C6: 34 | D6: =ROUND(C6/20, 0) -> 2 | E6: =F6*8 -> 344 | F6: 43 | G6: =ROUND(F6/20,0) -> 2 | H6: =I6*8 -> 712 | I6: 89 | J6: =ROUND(I6/20,0) -> 4 | K6: =L6*8 -> 256 | L6: 32 | M6: =ROUND(L6/20, 0) -> 2 | N6: 69 | O6: =N6/8 -> 8.625 | P6: =O6/20 -> 0.43125 | Q6: 195 | R6: =Q6/8 -> 24.375 | S6: =R6/20 -> 1.21875 | T6: 255 | U6: =T6/8 -> 31.875 | V6: =U6/20 -> 1.59375
A7: Architect | B7: =C7*8 -> 256 | C7: 32 | D7: =ROUND(C7/20, 0) -> 2 | E7: =F7*8 -> 344 | F7: 43 | G7: =ROUND(F7/20,0) -> 2 | H7: =I7*8 -> 720 | I7: 90 | J7: =ROUND(I7/20,0) -> 5 | K7: =L7*8 -> 296 | L7: 37 | M7: =ROUND(L7/20, 0) -> 2
A8: Tech Lead | B8: =C8*8 -> 440 | C8: 55 | D8: =ROUND(C8/20, 0) -> 3 | E8: =F8*8 -> 448 | F8: 56 | G8: =ROUND(F8/20,0) -> 3 | H8: =I8*8 -> 1120 | I8: 140 | J8: =ROUND(I8/20,0) -> 7 | K8: =L8*8 -> 408 | L8: 51 | M8: =ROUND(L8/20, 0) -> 3
A9: Dev1 | B9: =C9*8 -> 720 | C9: 90 | D9: =ROUND(C9/20, 0) -> 5 | E9: =F9*8 -> 768 | F9: 96 | G9: =ROUND(F9/20,0) -> 5 | H9: =I9*8 -> 1704 | I9: 213 | J9: =ROUND(I9/20,0) -> 11 | K9: =L9*8 -> 648 | L9: 81 | M9: =ROUND(L9/20, 0) -> 4 | N9: 660 | O9: =N9/8 -> 82.5 | P9: =O9/20 -> 4.125 | Q9: 1020 | R9: =Q9/8 -> 127.5 | S9: =R9/20 -> 6.375 | T9: 1860 | U9: =T9/8 -> 232.5 | V9: =U9/20 -> 11.625
A10: Dev2 | B10: =C10*8 -> 720 | C10: 90 | D10: =ROUND(C10/20, 0) -> 5 | E10: =F10*8 -> 768 | F10: 96 | G10: =ROUND(F10/20,0) -> 5 | H10: =I10*8 -> 1704 | I10: 213 | J10: =ROUND(I10/20,0) -> 11 | K10: =L10*8 -> 648 | L10: 81 | M10: =ROUND(L10/20, 0) -> 4
A11: Test Lead | B11: =C11*8 -> 352 | C11: 44 | D11: =ROUND(C11/20, 0) -> 2 | E11: =F11*8 -> 352 | F11: 44 | G11: =ROUND(F11/20,0) -> 2 | H11: =I11*8 -> 752 | I11: 94 | J11: =ROUND(I11/20,0) -> 5 | K11: =L11*8 -> 312 | L11: 39 | M11: =ROUND(L11/20, 0) -> 2
A12: Test Engineer | B12: =C12*8 -> 536 | C12: 67 | D12: =ROUND(C12/20, 0) -> 3 | E12: =F12*8 -> 600 | F12: 75 | G12: =ROUND(F12/20,0) -> 4 | H12: =I12*8 -> 1328 | I12: 166 | J12: =ROUND(I12/20,0) -> 8 | K12: =L12*8 -> 520 | L12: 65 | M12: =ROUND(L12/20, 0) -> 3 | N12: 81 | O12: =N12/8 -> 10.125 | P12: =O12/20 -> 0.50625 | Q12: 249 | R12: =Q12/8 -> 31.125 | S12: =R12/20 -> 1.55625 | T12: 360 | U12: =T12/8 -> 45 | V12: =U12/20 -> 2.25
A13: DBA | B13: =C13*8 -> 248 | C13: 31 | D13: =ROUND(C13/20, 0) -> 2 | E13: =F13*8 -> 248 | F13: 31 | G13: =ROUND(F13/20,0) -> 2 | H13: =I13*8 -> 632 | I13: 79 | J13: =ROUND(I13/20,0) -> 4 | K13: =L13*8 -> 208 | L13: 26 | M13: =ROUND(L13/20, 0) -> 1
A14: DB Developer | B14: =C14*8 -> 432 | C14: 54 | D14: =ROUND(C14/20, 0) -> 3 | E14: =F14*8 -> 456 | F14: 57 | G14: =ROUND(F14/20,0) -> 3 | H14: =I14*8 -> 1024 | I14: 128 | J14: =ROUND(I14/20,0) -> 6 | K14: =L14*8 -> 408 | L14: 51 | M14: =ROUND(L14/20, 0) -> 3
A15: UX | B15: =C15*8 -> 432 | C15: 54 | D15: =ROUND(C15/20, 0) -> 3 | E15: =F15*8 -> 424 | F15: 53 | G15: =ROUND(F15/20,0) -> 3 | H15: =I15*8 -> 768 | I15: 96 | J15: =ROUND(I15/20,0) -> 5 | K15: =L15*8 -> 288 | L15: 36 | M15: =ROUND(L15/20, 0) -> 2
A16: UI | B16: =C16*8 -> 520 | C16: 65 | D16: =ROUND(C16/20, 0) -> 3 | E16: =F16*8 -> 528 | F16: 66 | G16: =ROUND(F16/20,0) -> 3 | H16: =I16*8 -> 904 | I16: 113 | J16: =ROUND(I16/20,0) -> 6 | K16: =L16*8 -> 408 | L16: 51 | M16: =ROUND(L16/20, 0) -> 3
A17: Cloud Architect | B17: =C17*8 -> 160 | C17: 20 | D17: =ROUND(C17/20, 0) -> 1 | E17: =F17*8 -> 160 | F17: 20 | G17: =ROUND(F17/20,0) -> 1 | H17: =I17*8 -> 160 | I17: 20 | J17: =ROUND(I17/20,0) -> 1 | K17: =L17*8 -> 160 | L17: 20 | M17: =ROUND(L17/20, 0) -> 1
A18: DevOps Engineer | B18: =C18*8 -> 160 | C18: 20 | D18: =ROUND(C18/20, 0) -> 1 | E18: =F18*8 -> 160 | F18: 20 | G18: =ROUND(F18/20,0) -> 1 | H18: =I18*8 -> 160 | I18: 20 | J18: =ROUND(I18/20,0) -> 1 | K18: =L18*8 -> 160 | L18: 20 | M18: =ROUND(L18/20, 0) -> 1
A19: Totals | B19: =SUM(B5:B18) -> 5520 | C19: =SUM(C5:C18) -> 690 | D19: =SUM(D5:D18) -> 37 | E19: =SUM(E5:E18) -> 5936 | F19: =SUM(F5:F18) -> 742 | G19: =F19/20 -> 37.1 | H19: =SUM(H5:H18) -> 12400 | I19: =SUM(I5:I18) -> 1550 | J19: =ROUND(I19/20,0) -> 78 | K19: =SUM(K5:K18) -> 4976 | L19: =SUM(L5:L18) -> 622 | M19: =SUM(M5:M18) -> 33 | N19: =SUM(N5:N18) -> 921 | O19: =SUM(O5:O18) -> 115.125 | P19: =SUM(P5:P18) -> 5.75625 | Q19: =SUM(Q5:Q18) -> 1647 | R19: =SUM(R5:R18) -> 205.875 | ... V19: =SUM(V5:V18) -> 17.05
A20: User Stories | B20: ='Digitalized Invoice Effort'!B107+'Digitalized Invoice Effort'!A107 -> 36 | E20: ='Survey App Effort'!B148 -> 16 | H20: ='CAF Effort'!B251 -> 24 | K20: ='CWT Effort'!B66 -> 13 | N20: 5 | O20: 5 | P20: 5 | Q20: 15 | R20: 15 | S20: 15 | T20: 24
A21: Tasks | B21: ='Digitalized Invoice Effort'!C107 -> 60 | E21: ='Survey App Effort'!C148 -> 82 | H21: ='CAF Effort'!C251 -> 95 | K21: ='CWT Effort'!C66 -> 49 | N21: 22 | O21: 22 | P21: 22 | Q21: 27 | R21: 27 | S21: 27 | T21: 90
A22: Sub Tasks | B22: ='Digitalized Invoice Effort'!D107 -> 8 | E22: ='Survey App Effort'!D148 -> 44 | H22: ='CAF Effort'!D251 -> 125 | K22: ='Digitalized Invoice Effort'!A107 -> 5 | N22: 10 | O22: 10 | P22: 10 | Q22: 18 | R22: 18 | S22: 18 | T22: 68
A23: Web Forms | B23: ='Digitalized Invoice Effort'!E107 -> 82 | E23: ='Survey App Effort'!E148 -> 54 | H23: 120 | K23: ='CWT Effort'!E66 -> 22 | N23: 13 | O23: 13 | P23: 13 | Q23: 23 | R23: 23 | S23: 23 | T23: 37

Sheet Summary_old
A1: APP | B1: PM | C1: BA | D1: Architect | E1: Tech Lead | F1: Dev1 | G1: Dev2 | H1: Test Lead | I1: Test Engineer | J1: DBA | K1: DB Developer | L1: UX | M1: UI | N1: Cloud Architect | O1: DevOps Engineer | P1: App Effort (In Days | Q1: Months | R1: Hours
A2: Digitalised Invoice | B2: 34 | C2: 34 | D2: 32 | E2: 55 | F2: 90 | G2: 90 | H2: 44 | I2: 67 | J2: 31 | K2: 54 | L2: 54 | M2: 65 | N2: 20 | O2: 20 | P2: =SUM(Table712[[#This Row],[PM]:[DevOps Engineer]]) -> 690 | Q2: =Table712[[#This Row],[App Effort (In Days]]/22 -> 31.363636 | R2: =Table712[[#This Row],[App Effort (In Days]]*8 -> 5520
A3: Survey Application | B3: 42 | C3: 43 | D3: 43 | E3: 56 | F3: 96 | G3: 96 | H3: 44 | I3: 75 | J3: 31 | K3: 57 | L3: 53 | M3: 66 | N3: 20 | O3: 20 | P3: =SUM(Table712[[#This Row],[PM]:[DevOps Engineer]]) -> 742 | Q3: =Table712[[#This Row],[App Effort (In Days]]/22 -> 33.727273 | R3: =Table712[[#This Row],[App Effort (In Days]]*8 -> 5936
A4: CWT | B4: 32 | C4: 32 | D4: 37 | E4: 51 | F4: 81 | G4: 81 | H4: 39 | I4: 65 | J4: 26 | K4: 51 | L4: 36 | M4: 51 | N4: 20 | O4: 20 | P4: =SUM(Table712[[#This Row],[PM]:[DevOps Engineer]]) -> 622 | Q4: =Table712[[#This Row],[App Effort (In Days]]/22 -> 28.272727 | R4: =Table712[[#This Row],[App Effort (In Days]]*8 -> 4976
A5: CAF | B5: ='CAF Effort'!E250 -> 89 | C5: ='CAF Effort'!F250 -> 89 | D5: ='CAF Effort'!G250 -> 90 | E5: ='CAF Effort'!H250 -> 140 | F5: ='CAF Effort'!I250 -> 213 | G5: ='CAF Effort'!J250 -> 213 | H5: ='CAF Effort'!K250 -> 94 | I5: ='CAF Effort'!L250 -> 166 | ... M5: ='CAF Effort'!P250 -> 113 | N5: 20 | O5: 20 | P5: =SUM(Table712[[#This Row],[PM]:[DevOps Engineer]]) -> 1550 | Q5: =Table712[[#This Row],[App Effort (In Days]]/22 -> 70.454545 | R5: =Table712[[#This Row],[App Effort (In Days]]*8 -> 12400
A6: Total | B6: =SUM(B2:B5) -> 197 | C6: =SUM(C2:C5) -> 198 | D6: =SUM(D2:D5) -> 202 | E6: =SUM(E2:E5) -> 302 | F6: =SUM(F2:F5) -> 480 | G6: =SUM(G2:G5) -> 480 | H6: =SUM(H2:H5) -> 221 | I6: =SUM(I2:I5) -> 373 | ... O6: =SUM(O2:O5) -> 80 | P6: =SUM(Table712[[#This Row],[PM]:[DevOps Engineer]]) -> 3604 | Q6: =Table712[[#This Row],[App Effort (In Days]]/22 -> 163.81818 | R6: =Table712[[#This Row],[App Effort (In Days]]*8 -> 28832
A7: Exact Month | B7: =B6/20 -> 9.85 | C7: =C6/20 -> 9.9 | D7: =D6/20 -> 10.1 | E7: =E6/20 -> 15.1 | F7: =F6/20 -> 24 | G7: =G6/20 -> 24 | H7: =H6/20 -> 11.05 | I7: =I6/20 -> 18.65 | ... P7: =P6/20 -> 180.2
A8: Rounded - Head Count | B8: 2 | C8: 2 | D8: 2 | E8: 3 | F8: 4 | G8: 4 | H8: 2 | I8: 3 | J8: 1 | K8: 3 | L8: 2 | M8: 3 | N8: 1 | O8: 1
A12: CAF Values | B12: 89 | C12: 89 | D12: 90 | E12: 140 | F12: 213 | G12: 213 | H12: 94 | I12: 166 | J12: 79 | K12: 128 | L12: 96 | M12: 113 | N12: 20 | O12: 20

Sheet Power Apps Estimation
A2: Risk & Insurance Portal | B2: Access Creation & Initiation | C2: Requirements Gathering, User Story Creation, Sprint Backlogs, Acceptance Criteria | D2: Build & Test (Web & Mobile Applications) | M2: Reworks & UAT | N2: Go live & Hypercare | O2: Total Effort
B3: Month 1 - June | F3: Month 2 - July | J3: Month 3 - August
B4: Sprint 1 | D4: Sprint 2 | F4: Sprint 3 | H4: Sprint 4 | J4: Sprint 5 | L4: Sprint 6 | O4: =SUM(O7:O13) -> 921
A5: Weeks | B5: W1 | C5: W2 | D5: W3 | E5: W4 | F5: W5 | G5: W6 | H5: W7 | I5: W8 | J5: W9 | K5: W10 | L5: W11 | M5: W12 | N5: W13
A6: Developers | C6: 2 | D6: 2 | E6: 2 | F6: 2 | G6: 2 | H6: 2 | I6: 2 | J6: 2 | K6: 2 | L6: 2 | M6: 1 | N6: 1
A7: Efforts | B7: =B6*5*6 -> 0 | C7: =C6*5*6 -> 60 | D7: =D6*5*6 -> 60 | E7: =E6*5*6 -> 60 | F7: =F6*5*6 -> 60 | G7: =G6*5*6 -> 60 | H7: =H6*5*6 -> 60 | I7: =I6*5*6 -> 60 | ... N7: =N6*5*6 -> 30 | O7: =SUM(B7:N7) -> 660
A8: QA | F8: 0.3 | G8: 0.3 | H8: 0.3 | I8: 0.3 | J8: 0.3 | K8: 0.3 | L8: 0.3 | M8: 0.3 | N8: 0.3
A9: Effort | B9: =B8*6*5 -> 0 | C9: =C8*6*5 -> 0 | D9: =D8*6*5 -> 0 | E9: =E8*6*5 -> 0 | F9: =F8*6*5 -> 9 | G9: =G8*6*5 -> 9 | H9: =H8*6*5 -> 9 | I9: =I8*6*5 -> 9 | ... N9: =N8*6*5 -> 9 | O9: =SUM(B9:N9) -> 81
A10: BA | B10: 0.3 | C10: 0.3 | D10: 0.3 | E10: 0.3 | F10: 0.1 | G10: 0.1 | H10: 0.1 | I10: 0.1 | J10: 0.1 | K10: 0.1 | L10: 0.1 | M10: 0.1 | N10: 0.3
A11: Effort | B11: =B10*5*6 -> 9 | C11: =C10*5*6 -> 9 | D11: =D10*5*6 -> 9 | E11: =E10*5*6 -> 9 | F11: =F10*5*6 -> 3 | G11: =G10*5*6 -> 3 | H11: =H10*5*6 -> 3 | I11: =I10*5*6 -> 3 | ... N11: =N10*5*6 -> 9 | O11: =SUM(B11:N11) -> 69
A12: PM | B12: 0.3 | C12: 0.3 | D12: 0.3 | E12: 0.3 | F12: 0.3 | G12: 0.3 | H12: 0.3 | I12: 0.3 | J12: 0.3 | K12: 0.3 | L12: 0.3 | M12: 0.3 | N12: 0.1
A13: Effort | B13: =B12*5*6 -> 9 | C13: =C12*5*6 -> 9 | D13: =D12*5*6 -> 9 | E13: =E12*5*6 -> 9 | F13: =F12*5*6 -> 9 | G13: =G12*5*6 -> 9 | H13: =H12*5*6 -> 9 | I13: =I12*5*6 -> 9 | ... N13: =N12*5*6 -> 3 | O13: =SUM(B13:N13) -> 111
A17: Cadence | B17: Access Creation & Initiation | C17: Requirements Gathering, User Story Creation, Sprint Backlogs, Acceptance Criteria | D17: Build & Test (Web & Mobile Applications) | M17: Reworks & UAT | N17: Go live & Hypercare | O17: Total Effort
B18: Month 1 - June | F18: Month 2 - July | J18: Month 3 - August
B19: Sprint 1 | D19: Sprint 2 | F19: Sprint 3 | H19: Sprint 4 | J19: Sprint 5 | L19: Sprint 6 | O19: =SUM(O22:O28) -> 1647
A20: Weeks | B20: W1 | C20: W2 | D20: W3 | E20: W4 | F20: W5 | G20: W6 | H20: W7 | I20: W8 | J20: W9 | K20: W10 | L20: W11 | M20: W12 | N20: W13
A21: Developers | C21: 3 | D21: 3 | E21: 3 | F21: 3 | G21: 3 | H21: 3 | I21: 3 | J21: 3 | K21: 3 | L21: 3 | M21: 3 | N21: 1
A22: Efforts | B22: =B21*5*6 -> 0 | C22: =C21*5*6 -> 90 | D22: =D21*5*6 -> 90 | E22: =E21*5*6 -> 90 | F22: =F21*5*6 -> 90 | G22: =G21*5*6 -> 90 | H22: =H21*5*6 -> 90 | I22: =I21*5*6 -> 90 | ... N22: =N21*5*6 -> 30 | O22: =SUM(B22:N22) -> 1020
A23: QA | F23: 1 | G23: 1 | H23: 1 | I23: 1 | J23: 1 | K23: 1 | L23: 1 | M23: 1 | N23: 0.3
A24: Effort | B24: =B23*6*5 -> 0 | C24: =C23*6*5 -> 0 | D24: =D23*6*5 -> 0 | E24: =E23*6*5 -> 0 | F24: =F23*6*5 -> 30 | G24: =G23*6*5 -> 30 | H24: =H23*6*5 -> 30 | I24: =I23*6*5 -> 30 | ... N24: =N23*6*5 -> 9 | O24: =SUM(B24:N24) -> 249
A25: BA | B25: 0.5 | C25: 0.5 | D25: 0.5 | E25: 0.5 | F25: 0.5 | G25: 0.5 | H25: 0.5 | I25: 0.5 | J25: 0.5 | K25: 0.5 | L25: 0.5 | M25: 0.5 | N25: 0.5
A26: Effort | B26: =B25*5*6 -> 15 | C26: =C25*5*6 -> 15 | D26: =D25*5*6 -> 15 | E26: =E25*5*6 -> 15 | F26: =F25*5*6 -> 15 | G26: =G25*5*6 -> 15 | H26: =H25*5*6 -> 15 | I26: =I25*5*6 -> 15 | ... N26: =N25*5*6 -> 15 | O26: =SUM(B26:N26) -> 195
A27: PM | B27: 0.5 | C27: 0.5 | D27: 0.5 | E27: 0.5 | F27: 0.5 | G27: 0.5 | H27: 0.5 | I27: 0.5 | J27: 0.5 | K27: 0.5 | L27: 0.5 | M27: 0.5 | N27: 0.1
A28: Effort | B28: =B27*5*6 -> 15 | C28: =C27*5*6 -> 15 | D28: =D27*5*6 -> 15 | E28: =E27*5*6 -> 15 | F28: =F27*5*6 -> 15 | G28: =G27*5*6 -> 15 | H28: =H27*5*6 -> 15 | I28: =I27*5*6 -> 15 | ... N28: =N27*5*6 -> 3 | O28: =SUM(B28:N28) -> 183
A32: BBS | B32: Access Creation & Initiation | C32: Requirements Gathering, User Story Creation, Sprint Backlogs, Acceptance Criteria | D32: Build & Test (Web & Mobile Applications) | M32: Reworks & UAT | R32: Go live & Hypercare | S32: Total Effort
B33: Month 1 - June | F33: Month 2 - July | J33: Month 3 - August | N33: Month 4 - September
B34: Sprint 1 | D34: Sprint 2 | F34: Sprint 3 | H34: Sprint 4 | J34: Sprint 5 | L34: Sprint 6 | N34: Sprint 7 | P34: Sprint 8 | S34: =SUM(S37:S43) -> 2727
A35: Weeks | B35: W1 | C35: W2 | D35: W3 | E35: W4 | F35: W5 | G35: W6 | H35: W7 | I35: W8 | J35: W9 | K35: W10 | L35: W11 | M35: W12 | N35: W13 | O35: W14 | P35: W15 | Q35: W16 | R35: W17
A36: Developers | C36: 4 | D36: 4 | E36: 4 | F36: 4 | G36: 4 | H36: 4 | I36: 4 | J36: 4 | K36: 4 | L36: 4 | M36: 4 | N36: 4 | O36: 4 | P36: 4 | Q36: 4 | R36: 2
A37: Efforts | B37: =B36*5*6 -> 0 | C37: =C36*5*6 -> 120 | D37: =D36*5*6 -> 120 | E37: =E36*5*6 -> 120 | F37: =F36*5*6 -> 120 | G37: =G36*5*6 -> 120 | H37: =H36*5*6 -> 120 | I37: =I36*5*6 -> 120 | ... R37: =R36*5*6 -> 60 | S37: =SUM(B37:R37) -> 1860
A38: QA | F38: 1 | G38: 1 | H38: 1 | I38: 1 | J38: 1 | K38: 1 | L38: 1 | M38: 1 | N38: 1 | O38: 1 | P38: 1 | Q38: 1 | R38: 0.3
A39: Effort | B39: =B38*6*5 -> 0 | C39: =C38*6*5 -> 0 | D39: =D38*6*5 -> 0 | E39: =E38*6*5 -> 0 | F39: =F38*6*5 -> 30 | G39: =G38*6*5 -> 30 | H39: =H38*6*5 -> 30 | I39: =I38*6*5 -> 30 | ... R39: =R38*6*5 -> 9 | S39: =SUM(B39:R39) -> 369
A40: BA | B40: 0.5 | C40: 0.5 | D40: 0.5 | E40: 0.5 | F40: 0.5 | G40: 0.5 | H40: 0.5 | I40: 0.5 | J40: 0.5 | K40: 0.5 | L40: 0.5 | M40: 0.5 | N40: 0.5 | O40: 0.5 | P40: 0.5 | Q40: 0.5 | R40: 0.5
A41: Effort | B41: =B40*5*6 -> 15 | C41: =C40*5*6 -> 15 | D41: =D40*5*6 -> 15 | E41: =E40*5*6 -> 15 | F41: =F40*5*6 -> 15 | G41: =G40*5*6 -> 15 | H41: =H40*5*6 -> 15 | I41: =I40*5*6 -> 15 | ... R41: =R40*5*6 -> 15 | S41: =SUM(B41:R41) -> 255
A42: PM | B42: 0.5 | C42: 0.5 | D42: 0.5 | E42: 0.5 | F42: 0.5 | G42: 0.5 | H42: 0.5 | I42: 0.5 | J42: 0.5 | K42: 0.5 | L42: 0.5 | M42: 0.5 | N42: 0.5 | O42: 0.5 | P42: 0.5 | Q42: 0.5 | R42: 0.1
A43: Effort | B43: =B42*5*6 -> 15 | C43: =C42*5*6 -> 15 | D43: =D42*5*6 -> 15 | E43: =E42*5*6 -> 15 | F43: =F42*5*6 -> 15 | G43: =G42*5*6 -> 15 | H43: =H42*5*6 -> 15 | I43: =I42*5*6 -> 15 | ... R43: =R42*5*6 -> 3 | S43: =SUM(B43:R43) -> 243
A47: Since in Power Apps, developers will not be able to publish at the same time, hence the developers needs to be considered in different time zones or working hours, with overlapping hours
A48: The timeline and estimation is entirely based on the captured features. Any change in the Scope will have to change the timeline.

Sheet Resource Loading
A1: Head Count | B1: Role | C1: Monthly Loading | D1: Hourly Loading | E1: FNT 1 | F1: FNT 2 | G1: FNT 3 | H1: FNT 4 | I1: FNT 5 | J1: FNT 6 | K1: FNT 7 | L1: FNT 8 | M1: FNT 9 | N1: FNT 10 | O1: FNT 11 | P1: FNT 12 | Q1: FNT 13 | R1: FNT 14 | S1: FNT 15 | T1: FNT 16 | U1: FNT 17 | V1: FNT 18 | W1: FNT 19 | X1: FNT 20
A2: 0.66666667 | B2: Project Manager | C2: 9 | D2: 5.33
A3: 1 | B3: Senior BA | C3: 8 | D3: 8
A4: 1 | B4: Presales Solution Architect | C4: 3 | D4: 6
A5: 1 | B5: Senior Delivery Manager | C5: 2 | D5: 5.33
A6: 0.66666667 | B6: Technical Architect | C6: 9 | D6: 5.33
A7: 1 | B7: .Net Technical Lead | C7: 8 | D7: 8
A8: 1 | B8: Front End Technical Lead | C8: 8 | D8: 8
A9: 2 | B9: Senior .Net Developer | C9: 9 | D9: 16
A10: 1 | B10: Junior .Net Developer | C10: 9 | D10: 8
A11: 0.25 | B11: Database Admin / Architect | C11: 7 | D11: 2
A12: 1 | B12: SQL Developer | C12: 7 | D12: 8
A13: 1 | B13: Senior SQL Developer | C13: 7 | D13: 8
... A23: 1 | B23: Senior Mobile Developer | C23: 6 | D23: 8

Sheet BBS
A1: From Name | B1: EPIC | C1: User Story | D1: Task | E1: Sub Task | F1: PM | G1: BA | H1: Architect | I1: Tech Lead | J1: Dev1 | K1: Dev2 | L1: QA Tester | M1: Test Engineer | N1: DBA | O1: DB Developer | P1: UX | Q1: UI
B2: 1. Behavior Based Safety Application
B3: 35+ | C3: New Site | D3: Create Site | F3: 1 | G3: 1 | I3: 1 | J3: 1 | K3: 1
D4: Create Groups and Permissions | J4: 1 | K4: 1
D5: Create Table structure to map all the tables | J5: 6 | K5: 6
D6: Create Lists in Sharepoint | J6: 4 | K6: 4
D7: Create Views for the list | J7: 2 | K7: 2
B9: PowerApps
A10: Login Screen | C10: Login Screen | D10: Create New Screen with login Button. | F10: 1 | G10: 1 | I10: 1 | J10: 3 | K10: 3 | L10: 3
A13: Dashborad | C13: Dashborad | D13: Create new sceen with UI Navigation | F13: 1 | G13: 1 | I13: 1 | J13: 1 | K13: 1 | L13: 3
D14: MU Coke BBS Compliance per site bar graph | E14: Power BI Report | J14: 5 | K14: 5
D15: MU Average BBS Compliance per Calendar Period line graph. | E15: Power BI Report | J15: 5 | K15: 5
D16: Banner with Notification message showing the pending Approvals | J16: 2.5 | K16: 2.5
D17: Search and Filters | J17: 2 | K17: 2
A19: RCA Home | C19: RCA Home | D19: Create new sceen with UI Navigation (Header,home,Back,Menu) | F19: 1 | G19: 1 | I19: 1 | J19: 2 | K19: 2 | L19: 3
D20: Display all the Root Cause Analysis submitted for Approval | J20: 1 | K20: 2
D21: RCA displays table of Date Period, Plant, perfomed by, Location, Status and action | J21: 2 | K21: 2
D22: Sorting functions for each soloumns | J22: 1.5 | K22: 1.5
A24: Perform RCA | C24: Perform RCA | D24: Create new sceen with UI Navigation (Header,home,Back,Menu) | F24: 1 | G24: 1 | I24: 1 | J24: 2 | K24: 2 | L24: 3
D25: View RCA details | J25: 2 | K25: 2
D26: Approve/ Reject buttons | E26: By clicking on approve an Approve Confirmation pop up message will appear. Click Approve to proceed or click Cancel and close icon will dismiss the current screen display. | J26: 2 | K26: 2
D27: Display Notification on Approve/reject | E27: If RCA submitted was approved “RCA submitted successfully approved.” and if rejwected “RCA submitted successfully Rejected" | J27: 1.5 | K27: 1.5
C29: Reports | D29: Contains all reports for below modules.
A30: Observation Report | D30: Observation Report | E30: Create new sceen with UI Navigation (Header,home,Back,Menu)Display Table listing details of Region, Sites, Observers, Date Observed, Area Observed, Task Observed. Each column listing can be sorted using the sorting icon beside each table column title Filter search and clear function Export report Icon | F30: 1 | G30: 1 | I30: 1 | J30: 8 | K30: 8 | L30: 2
A31: RCA Report | D31: RCA Report | E31: Create new sceen with UI Navigation (Header,home,Back,Menu) ,Display Table listing details ofof Date Period, Site, Performed by, location and Status. Each column listing can be sorted using the sorting icon beside each table column title Filter search and clear function Export report Icon | F31: 1 | G31: 1 | I31: 1 | J31: 8 | K31: 8 | L31: 2
A32: Effectiveness Report | D32: Effectiveness Report | E32: Create new sceen with UI Navigation (Header,home,Back,Menu), Display Table listing details of Period, Sites, Region, Critical Behaviour, Target Number of Answers, Actual Number of Answers, YES/NO/NA count, % Safe Behaviour and % Unsafe Behaviour. Each column listing can be sorted using the sorting icon beside each table column title Filter search and clear function Export report Icon | F32: 1 | G32: 1 | I32: 1 | J32: 8 | K32: 8 | L32: 2
A33: Observation Compliance Report | D33: Observation Compliance Report | E33: Create new sceen with UI Navigation (Header,home,Back,Menu), Display Table listing details of Period, Site, Region, Critical Behavior, Target Number of Answers, Actual Number of Answers, YES/NO/NA count, % Safe Behavior and % Unsafe Behavior. Each column listing can be sorted using the sorting icon beside each table column title. Filter search and clear function Export report Icon | F33: 1 | G33: 1 | I33: 1 | J33: 8 | K33: 8 | L33: 2
A34: BBS Compliance Report | D34: BBS Compliance Report | E34: Create new sceen with UI Navigation (Header,home,Back,Menu),Display Table listing details of Region, Plant, Period, Observation Compliance, % Observation, Unsafe Behavior, % Reduction, % Effectiveness, BBS Compliance for the Period and YTD BBS Compliance. Each column listing can be sorted using the sorting icon beside each table column title Filter search and clear function Export report Icon | F34: 1 | G34: 1 | I34: 1 | J34: 8 | K34: 8 | L34: 2
A36: Admin Screen | C36: Admin Site-Maintaince | D36: Admin Site contains below sub-tab | J36: 3 | K36: 3 | L36: 1.5
A37: Questions | D37: Questions | E37: Create new sceen with UI Navigation (Header,home,Back,Menu) ,Display List of Questions Edit/Deactive question Add new question | F37: 1 | G37: 1 | I37: 1 | J37: 4 | K37: 4 | L37: 1.5
A38: 445 Calendar | D38: 445 Calendar | E38: Create new sceen with UI Navigation (Header,home,Back,Menu), Display List Year, Period, Week, Start Date, and End date. Table be filtered by period and sorted per column. Download/Upload button to Download/Upload calendar | F38: 1 | G38: 1 | I38: 1 | J38: 4 | K38: 4 | L38: 2
A39: Target Definition | D39: Target Definition | E39: Create new sceen with UI Navigation (Header,home,Back,Menu), displays Year, National BBS Compliance Target (%), Weekly Observation Target per user, Weekly Observation Target effectivity date and Action. Table be filtered by period and sorted per column. Add New Target, Edit target | F39: 1 | G39: 1 | I39: 1 | J39: 5 | K39: 5 | L39: 2
A40: User Maintenance | C40: (Can be done for roles is sharepoint) | D40: User Maintenance | E40: Create new sceen with UI Navigation (Header,home,Back,Menu), Table listing displays Name, Email Address, Site, User Role, Date Added, Last Access, Active and Action. Filter and sort by columns. Add New User, edit/delete user role. Activate or deactivate users. | F40: 1 | G40: 1 | I40: 1 | J40: 5 | K40: 5 | L40: 2
A41: User Activation History | C41: (Can be done for roles is sharepoint) | D41: User Activation History | E41: Table listing displays User, Is Active Status, Site, User Role, Created Date, Date Added. Sort and filter by columns. Edit history | F41: 1 | G41: 1 | I41: 1 | J41: 4 | K41: 4 | L41: 2
A42: Unit Maintenance | D42: Unit Maintenance | E42: Create new sceen with UI Navigation (Header,home,Back,Menu), Table listing displays Name of Unit, Date Added, Active Status and Action. Filter and search. Add new Unit, Edit unit | F42: 1 | G42: 1 | I42: 1 | J42: 5 | K42: 5 | L42: 2
A43: Unit Detail Maintenance | D43: Unit Detail Maintenance | E43: Create new sceen with UI Navigation (Header,home,Back,Menu), 3 sub Units-Commercial unit, Logistic unit and Manufacturing Unit. For each unit Filter and search. Add new Unit, Edit unit | F43: 1 | G43: 1 | I43: 1 | J43: 5 | K43: 5 | L43: 2
B44: Power Automate flows | C44: Email Notification | D44: Create a power automate flow for email notifications | J44: 4 | K44: 4 | L44: 2
C45: Export to excel | D45: create power automate flow to export the gallery etails | J45: 4 | K45: 4 | L45: 2
B47: 2. Driver - Behavior Based Safety Application
B48: Sharepoint | C48: New Site | D48: Create Site | F48: 1 | G48: 1 | I48: 1 | J48: 1 | K48: 1
...

Sheet Cadence
A1: Form Name | B1: EPIC | C1: User Story | D1: Task | E1: Sub Task | F1: PM | G1: BA | H1: Architect | I1: Tech Lead | J1: Dev in days | K1: Dev2 | L1: Test Lead | M1: QA Tester | N1: DBA | O1: DB Developer | P1: UX | Q1: UI
A2: Announcement | B2: Mobile Application | C2: Announcement | D2: Announcement Details | F2: 1 | G2: 1 | I2: 1 | J2: 1 | M2: 6
D3: Weekly Planner -Schedule sessions for the riders -Create a new session -Select drivers -Color coded for drivers for threshold criteria -Calendar view of all schedules | J3: 5
A4: DSP Route Ride | C4: DSP Route Ride | D4: Dashboard -Date filters -Search -Dashboard reports of all outlets that answers yes to the survey -Click graph to show survey result for the outlets | F4: 1 | G4: 1 | I4: 1 | J4: 3 | M4: 6
D5: Team Profile - DSP Rider information -Summary, Current Performance, Timeline | J5: 3
A6: DSP Route Ride | C6: Route Ride Session | D6: Start session -DSP Attendance form -Outlets selection (Choice) - Action items (Yes/No) Session Summary -4 input fields Further Remarks Remarks Input fields (Opportunities, Next Steps, Remarks etc.) Signature (can be desinatory digital signature or signature using pen input) End Session | F6: 1 | G6: 1 | I6: 1 | J6: 5 | M6: 5
D7: Summary -opportunities (Dynamic input fields) Current Performance -Training objectives etc. Timeline -Past activity -Audit logs like feature -Calendar view and click to view the activity | J7: 5
A8: Dashboard | C8: AAA+ Survey | D8: Dashboard | E8: 5 category reports (Available, Alam na meron, Ayos ang presyo, Dapat Malamig, Tottal AAA+ score) -Date filter -View Survey results | F8: 1 | G8: 1 | I8: 1 | J8: 5 | M8: 6
A9: Survey Form | D9: Survey Form | E9: Driver can only see this screen if they have a session scheduled -Display an info message Choose outlets and answer the form Form design is multiple input fields | J9: 5
A10: Survey Results | D10: Survey Results | E10: 2 Tab unsyn and sync AAA+ and Glass survey review Sync all survey/ Sync today | J10: 3
A11: Enroll Outlet | C11: Outlet Enrollment | D11: Enroll Outlet | E11: Fill form to enroll and outlet | F11: 1 | G11: 1 | I11: 1 | J11: 3 | M11: 5
A12: Outlets | D12: Outlets | E12: Outlet results (sync, unsyn tab to view each) Unsyc may be edited | J12: 3
A13: AD Dashboard | C13: AD Dashboard | D13: Power BI | E13: Need to understand if any modifications required or data can be directly connected | F13: 1 | G13: 1 | I13: 1 | J13: 5
A15: Survey Questions | B15: Web Application | C15: AAA+/Glass survey | D15: Survey Questions | E15: Survey Forms Searching questions Add New -Name -Questions (ability to add) -Question forms (This is dynamic needs to check) preview Delete Status (currently as colored icons) Edit | F15: 1 | G15: 1 | I15: 1 | J15: 5 | M15: 6
A16: Survey Reasons | D16: Survey Reasons | E16: Add survey reasons Search *Similar to survey forms in functionality | J16: 3
A17: Survey Schedule | D17: Survey Schedule | E17: Add schedule -New schedule form -Criterias and rules on some fields Upload Schedule -As per the export excel file format Filters/search/reset etc. -Download functonality Export to excel functionality (Could be power automate connected to SP) | J17: 3
A18: Report | D18: Report | E18: Data dashboard similar to survey forms Export/Download to excel functionality Filters Views | J18: 3
A19: Survey Questions | C19: Route Ride | D19: Survey Questions | E19: Similar to AAA survey questions All survey questions inputted here will be input in the AAA survey questions | F19: 1 | G19: 1 | I19: 1 | J19: 3 | M19: 6
A20: Route Ride Threshold criteria | D20: Route Ride Threshold criteria | E20: Configuration data Admin configurations for survey data criteria | J20: 5
A21: Objectives | D21: Objectives | E21: Objective data view Add new | J21: 2
A22: Route Ride Report | D22: Route Ride Report | E22: Data view of all route ride results Filters, search Export summary (From route ride dashboard) Export functionality | J22: 3
A23: Glass Survey | C23: Glass Survey | D23: Survey Questions | E23: Survey Forms Searching questions Add new preview Delete Status (currently as colored icons) Edit | F23: 1 | G23: 1 | I23: 1 | J23: 3 | M23: 6
A24: Report | D24: Report | E24: Data dashboard similar to survey forms Export/Download to excel functionality Filters Views | J24: 3
A25: Survey Frequency | C25: Survey Frequency | D25: Data view to view next visit for AAA and glass Filters Seach Reset | F25: 1 | G25: 1 | I25: 1 | J25: 3
A26: DSP Attendance | C26: DSP Attendance | D26: Similar to Survey reports/questions with data view All reports from mobile app Export funcitonality | F26: 1 | G26: 1 | I26: 1 | J26: 3 | M26: 4
A27: Enrolled outlets | C27: Enrolled outlets | D27: Similar to DSP reports/questions with data view All reports from mobile app Export funcitonality | F27: 1 | G27: 1 | I27: 1 | J27: 3 | M27: 4
A28: User Maintenance | C28: User Maintenance | D28: Announcements | E28: Data view Add announcements -Form to add new -Image upload Upload Edit Delete Export Filters/Search etc. Download template (This can be done backend) | F28: 1 | G28: 1 | I28: 1 | J28: 3 | M28: 6
D29: Survey Limit | E29: Data View Create New -Form to add new | I29: 1 | J29: 3
C31: Email Notifications | I31: 1 | J31: 2 | M31: 4
C33: DB Configuration | I33: 1 | J33: 5
A34: =COUNTA(A2:A33) -> 23 | B34: =COUNTA(B2:B33) -> 2 | C34: =COUNTA(C2:C33) -> 15 | D34: =COUNTA(D2:D33) -> 27 | E34: =COUNTA(E2:E33) -> 18 | F34: =SUM(F2:F33) -> 13 | G34: =SUM(G2:G33) -> 13 | H34: =SUM(H2:H33) -> 0 | I34: =SUM(I2:I33) -> 16 | J34: =SUM(J2:J33) -> 101 | K34: =SUM(K2:K33) -> 0 | L34: =SUM(L2:L33) -> 0 | M34: =SUM(M2:M33) -> 64 | ... Q34: =SUM(Q2:Q33) -> 0
D35: Days
B36: Total Development hours | C36: 808 | D36: 101
B37: Total Testing Hours | C37: 256 | D37: 32
B38: Requirement Gathering Hours | C38: 40 | D38: 5
B39: Data Migration | C39: 40 | D39: 5
B40: UAT | C40: 64 | D40: 8
B41: Go live
C43: 1208

Sheet Risk & Insurance
A1: From Name | B1: EPIC | C1: User Story | D1: Task | E1: Sub Task | F1: PM | G1: BA | H1: Architect | I1: Tech Lead | J1: DEV (Hours) | K1: QA Tester | L1: DBA | M1: DB Developer | N1: UX | O1: UI
B2: Mock Up Screens
B3: PowerApps | C3: Prepare Mockup Screens | D3: Create the Mockup Screens for all features | F3: 1 | G3: 1 | I3: 1 | J3: 30
B5: Sharepoint | C5: Sharepoint Site creation- Backend | D5: Create Site | F5: 1 | G5: 1 | I5: 1 | J5: 1
D6: Create Groups and Permissions | J6: 1
D7: Create Table structure to map all the tables | J7: 12
D8: Create Lists in Sharepoint | J8: 12
D9: Create Views for the list | J9: 6
A11: Login | B11: PowerApps | C11: Login Screen | D11: Create New Screen for to Login as Roles | E11: Banner, login button | F11: 1 | G11: 1 | I11: 1 | J11: 15 | K11: 4
D12: Bug fixig | J12: 3
A14: Admin Home | C14: Admin Home Screen | D14: Create New screen with UI Navigations | F14: 1 | G14: 1 | I14: 1 | J14: 5 | K14: 5
D15: Create Gallery to show the Master List of Vechiles details | J15: 15
D16: Create Search and Sorting Function based of Insurance type | J16: 6
D17: Bug fixig | J17: 5
C19: Maintenance Modules | D19: Create New Screen to Add/Update Below Modules | F19: 1 | G19: 1 | I19: 1 | J19: 8
A20: Users | D20: Users | E20: users (Requestor,Broker,Claim Approver, Loa Approver) can be created, this consists of search by filter, reset and action which includes edit and delete. | J20: 24 | K20: 6
E21: Testing and Bug fixig | J21: 5
A22: Claims | D22: Claims Documents | E22: Search, filter, to create new documnet type. | J22: 18 | K22: 6
E23: Testing and Bug fixig | J23: 4
A24: Service Centers | D24: Service centers | E24: search, reset and to create new service center which also includes the action of edit and delete | J24: 18 | K24: 6
E25: Testing and Bug fixig | J25: 4
A26: Adjusters | D26: Adjusters | E26: Actions including edit, delete and create new adjusters. Search and filter | J26: 18 | K26: 6
E27: Testing and Bug fixig | J27: 4
A28: Regions | D28: Regions | E28: Add new ,delete,Edit Regions. Search and filter fuction | J28: 18 | K28: 6
E29: Testing and Bug fixig | J29: 4
A30: Plants | D30: Plants | E30: Add new ,delete, Edit Plants. Search and filter fuction | J30: 18 | K30: 6
E31: Testing and Bug fixig | J31: 4
A32: Vechile Types | D32: Vehicle types | E32: Add new, delete, Edit Vechile type. Search and filter fuction | J32: 18 | K32: 6
E33: Testing and Bug fixig | J33: 4
A34: Asset Class | D34: Asset class | E34: Add new, delete, Edit Asset class. Search and filter fuction | J34: 18 | K34: 6
E35: Testing and Bug fixig | J35: 4
C37: Requestor Screen | D37: Gallery list to show cliams submitted | F37: 1 | G37: 1 | I37: 1 | J37: 14 | K37: 8
D38: Create Search for claims based on data range | J38: 4
D39: Button to create a claim | J39: 3
D40: Create form - Includes Motor vehicle, Claim type and Documents | J40: 6 | K40: 3
D41: Submit function to save the details | J41: 3
D42: Bug fixig | J42: 8
A44: Claims Documents | C44: View Screen | D44: View the claim form | F44: 1 | G44: 1 | I44: 1 | J44: 14 | K44: 6
D45: Can edit/upload document | J45: 4
D46: Submit function to save the details | J46: 6
...

Sheet CAF Effort
A1: EPIC | B1: User Story | C1: Task | D1: Sub Task | E1: PM | F1: BA | G1: Architect | H1: Tech Lead | I1: Dev1 | J1: Dev2 | K1: Test Lead | L1: Test Engineer | M1: DBA | N1: DB Developer | O1: UX | P1: UI
B2: Customer Login | E2: 5 | F2: 5 | G2: 5 | H2: 8 | I2: 10 | J2: 10 | K2: 3 | L2: 6 | M2: 1 | N2: 1 | O2: 2 | P2: 2
C3: Get Link
C4: Update Details
C5: Verify and Login
C6: Authorization
C7: Forgot Password
C8: Back to email
C9: SSO Integration
B10: Admin Dashbaord | E10: 1 | F10: 1 | G10: 1 | H10: 2 | I10: 2 | J10: 2 | K10: 1 | L10: 2 | M10: 2 | N10: 3 | O10: 2 | P10: 3
C11: Menu
C12: List View
B13: Admin Portal
C14: Config Setup | E14: 1 | F14: 1 | G14: 1 | H14: 2 | I14: 2 | J14: 2 | K14: 1 | L14: 2 | M14: 2 | N14: 3 | O14: 2 | P14: 4
C15: Admin User Setup | E15: 2 | F15: 2 | G15: 2 | H15: 3 | I15: 5 | J15: 5 | K15: 1 | L15: 3 | M15: 1 | N15: 3 | O15: 2 | P15: 3
D16: Search
D17: List View
D18: Reset
D19: Add Existing User
D20: List view
D21: Add all
D22: Cancel
D23: List View
D24: Remove
C25: Role Details Setup | E25: 2 | F25: 2 | G25: 2 | H25: 3 | I25: 5 | J25: 5 | K25: 1 | L25: 3 | M25: 1 | N25: 3 | O25: 2 | P25: 3
D26: Auto Create Role Setup
D27: Save
D28: Remove
D29: List View
C30: Route Code Email Setup
C31: General Trade | E31: 2 | F31: 2 | G31: 2 | H31: 3 | I31: 5 | J31: 5 | K31: 1 | L31: 3 | M31: 1 | N31: 3 | O31: 2 | P31: 3
D32: List View
D33: Select File & Import Data
D34: Download Data
D35: Setup Data
D36: Save
C38: Modern Trade | E38: 1 | F38: 1 | G38: 1 | H38: 2 | I38: 2 | J38: 2 | K38: 1 | L38: 2 | M38: 2 | N38: 3 | O38: 2 | P38: 3
D39: List View
B40: Audit Logs | E40: 3 | F40: 3 | G40: 3 | H40: 4 | I40: 8 | J40: 8 | K40: 3 | L40: 5 | M40: 3 | N40: 5 | O40: 3 | P40: 5
C41: List View
...

Sheet CWT Effort
A1: EPIC | B1: User Story | C1: Task | D1: Sub Task | E1: Web Forms | F1: PM | G1: BA | H1: Architect | I1: Tech Lead | J1: Dev1 | K1: Dev2 | L1: Test Lead | M1: Test Engineer | N1: DBA | O1: DB Developer | P1: UX | Q1: UI
B2: Logo & Menu | E2: Authentication & Authorization | F2: 1 | G2: 1 | H2: 1 | I2: 2 | J2: 3 | K2: 3 | L2: 1 | M2: 2 | N2: 1 | O2: 2 | P2: 2 | Q2: 3
C3: Login Lable | E3: Reports
C4: Logo | E4: Extract
C5: Logout | E5: List View
C6: App Menu items | E6: Certificates
B7: Login Feature | E7: Preview | F7: 2 | G7: 2 | H7: 3 | I7: 4 | J7: 6 | K7: 6 | L7: 2 | M7: 3 | N7: 1 | O7: 2 | P7: 2 | Q7: 3
C8: Login | E8: List View
C9: Remember Me | E9: Vendors
C10: Forgot Password | E10: Bulk Upload
C11: Authorization | E11: Add
C12: Logout | E12: Import
B13: Certificates | E13: Edit | F13: 3 | G13: 3 | H13: 3 | I13: 6 | J13: 8 | K13: 8 | L13: 3 | M13: 5 | N13: 1 | O13: 2 | P13: 2 | Q13: 3
C14: Search | E14: Maintenence
C15: Preview | E15: Users List
C16: List View | E16: Create User
C17: Download | E17: Edit User
C18: Back | E18: Audit Lots
B19: Vendors | E19: CWT Changes | F19: 3 | G19: 3 | H19: 4 | I19: 6 | J19: 9 | K19: 9 | L19: 3 | M19: 6 | N19: 2 | O19: 5 | P19: 3 | Q19: 5
C20: Search | E20: Configuration
C21: List View | E21: Tax Codes
C22: Create Vendor | E22: Bulk Upload
C23: Exxtract Vendors | E23: Create Tax Codes
C24: Edit Vendor
C25: Bulk Upload
C26: Cancel
A27: Maintainance
B28: Users | F28: 2 | G28: 2 | H28: 3 | I28: 4 | J28: 6 | K28: 6 | L28: 4 | M28: 6 | N28: 3 | O28: 5 | P28: 3 | Q28: 4
C29: Search
C30: List View
C31: Create User
C32: Edit User
C33: Delete User
C34: Cancel
B35: Audit Logs | F35: 2 | G35: 2 | H35: 2 | I35: 2 | J35: 4 | K35: 4 | L35: 2 | M35: 4 | N35: 2 | O35: 4 | P35: 2 | Q35: 3
C36: Search
C37: List View
B38: CWT Changes | F38: 2 | G38: 2 | H38: 2 | I38: 2 | J38: 4 | K38: 4 | L38: 2 | M38: 4 | N38: 2 | O38: 4 | P38: 2 | Q38: 3
C39: Search
C40: List View
...

Sheet Digitalized Invoice Effort
A1: Epic | B1: User Story | C1: Task | D1: Sub Task | E1: Web Forms | F1: PM | G1: BA | H1: Architect | I1: Tech Lead | J1: Dev1 | K1: Dev2 | L1: Test Lead | M1: Test Engineer | N1: DBA | O1: DB Developer | P1: UX | Q1: UI | R1: Cloud Architect | S1: DevOps Engineer
A2: Login Feature | E2: Dashboard | R2: 20 | S2: 20
B3: Login | E3: Reports | F3: 1 | G3: 1 | H3: 2 | I3: 2 | J3: 3 | K3: 3 | L3: 1 | M3: 2 | N3: 1 | O3: 1 | P3: 2 | Q3: 2
B4: SSO | E4: Audit Logs
B5: Authorization | E5: Print Logs
B6: Password Change | E6: Approver Logs
B7: Logout | E7: Email Logs
A8: Dashboard | E8: Invoice Logs | F8: 1 | G8: 1 | H8: 1 | I8: 2 | J8: 3 | K8: 3 | L8: 2 | M8: 1 | N8: 1 | O8: 2 | P8: 3 | Q8: 3
B9: Total Count of Invoices | E9: Maintenance
B10: Total amount due | E10: Approver List
B11: total count of re-print | E11: Add
B12: Total count of pending | E12: Edit
B13: Search - Location filter | E13: Bulk Add
B14: Search - Dare filter | E14: Select
A15: Report | E15: Customer | F15: 2 | G15: 2 | H15: 2 | I15: 3 | J15: 5 | K15: 5 | L15: 2 | M15: 3 | N15: 1 | O15: 2 | P15: 2 | Q15: 3
B16: Filter Report | E16: Add
B17: Export Report | E17: Edit
B18: Report List View | E18: Bulk Add
E19: Select
A20: Audit Logs | E20: Customer Group | F20: 4 | G20: 4 | H20: =SUM(H21:H30) -> 0 | I20: 8 | J20: 12 | K20: 12 | L20: 8 | M20: 12 | N20: 4 | O20: 8 | P20: 8 | Q20: 8
B21: Print Log | C21: Filter Search | E21: Add
C22: Export Report | E22: Edit
C23: List View | E23: Bulk Add
B24: Approver Log | C24: Filter Search | E24: Select
C25: Export Report | E25: Configuration
C26: List View | E26: Commercial Unit
B27: Email Log | C27: Filter Search | E27: Add
C28: Export Report | E28: Edit
C29: List View | E29: Bulk Add
B30: Invoice Log | C30: Filter Search | E30: Select
C31: Export Report | E31: Invoice Footer
C32: List View | E32: Add
A33: Maintainance | E33: Edit | F33: 2 | G33: 2 | H33: 2 | I33: 3 | J33: 5 | K33: 5 | L33: 2 | M33: 3 | N33: 2 | O33: 3 | P33: 3 | Q33: 4
B34: Approver List | E34: Bulk Add
C35: Search Filter | E35: Select
C36: Approvers without location | E36: Location
C37: List View | E37: Add
C38: Bulk Upload | E38: Edit
D39: Download Template | E39: Bulk Add
D40: Upload file | E40: Select
...

Sheet Survey App Details
A1: EPIC | B1: User Story | C1: Task | D1: Sub Task | E1: PM | F1: BA | G1: Architect | H1: Tech Lead | I1: Dev1 | J1: Dev2 | K1: Test Lead | L1: Test Engineer | M1: DBA | N1: DB Developer | O1: UX | P1: UI | Q1: Cloud Architect | R1: DevOps Engineer
B2: Login features
C3: Login
C4: Forgot password
C5: Remember Me
C6: Logout
C7: Authorization
B8: Side Pane
C9: Account settings | D9: User details
D10: Change password
C11: Menu
A12: Users
B13: Manage users
C14: Search
C15: Reset
C16: Export
C17: List view
C18: Add user
C19: Add multiple user | D19: Download user template
D20: Download user assignment template
D21: upload file
D22: Edit user
D23: Cancel & Back
A24: User assignment
B25: Department
C26: Search
C27: Export
C28: List view
C29: Add Department
C30: Edit Department
B31: Customer group
C32: Search
C33: Export
C34: List view
C35: Add customer group
C36: Add multiple customer group | D36: Download template
D37: Upload file
D38: Cancel & Back
C39: Edit customer group
B40: Territory
...

Sheet Survey App Effort
A1: EPIC | B1: User Story | C1: Task | D1: Sub Task | E1: Web Forms | F1: PM | G1: BA | H1: Architect | I1: Tech Lead | J1: Dev1 | K1: Dev2 | L1: Test Lead | M1: Test Engineer | N1: DBA | O1: DB Developer | P1: UX | Q1: UI | R1: Cloud Architect | S1: DevOps Engineer
B2: Login features | E2: Authentication & Authorization | F2: 1 | G2: 1 | H2: 2 | I2: 2 | J2: 3 | K2: 3 | L2: 1 | M2: 2 | N2: 1 | O2: 1 | P2: 2 | Q2: 2
C3: Login | E3: Send Notification
C4: Forgot password | E4: Windows Schedular
C5: Remember Me | E5: Users
C6: Logout | E6: Add
C7: Authorization | E7: Manage
B8: Side Pane | E8: Bulk Add | F8: 1 | G8: 1 | H8: 1 | I8: 1 | J8: 2 | K8: 2 | L8: 1 | M8: 1 | N8: 1 | O8: 1 | P8: 1 | Q8: 2
C9: Account settings | E9: User Assignment
D10: User details | E10: Department
D11: Change password | E11: Add
C12: Menu | E12: Customer Group
A13: Users | E13: Add
